<?xml version="1.0" encoding="utf-8"?>
<!-- This URDF was automatically created by SolidWorks to URDF Exporter! Originally created by Stephen Brawner (brawner@gmail.com) 
     Commit Version: 1.6.0-4-g7f85cfe  Build Version: 1.6.7995.38578
     For more information, please see http://wiki.ros.org/sw_urdf_exporter -->
<robot
  name="robot_des">
  
  <link
    name="base_link">
    <inertial>
      <origin
        xyz="-0.000428130552795045 -0.021915627601754 0.2"
        rpy="0 0 0" />
      <mass
        value="4.68126788295179" />
      <inertia
        ixx="0.0145873193919006"
        ixy="-6.80283507311823E-06"
        ixz="3.04984884541059E-07"
        iyy="0.0124505441321933"
        iyz="-1.59907342304969E-06"
        izz="0.0234128160904748" />
    </inertial>
    <visual>
      <origin
        xyz="0 0 0"
        rpy="0 0 0" />
      <geometry>
        <mesh
          filename="package://robot_des/meshes/base_link.STL" />
      </geometry>
      <material
        name="">
        <color
          rgba="0.752941176470588 0.752941176470588 0.752941176470588 1" />
      </material>
    </visual>
    <collision>
      <origin
        xyz="0 0 0"
        rpy="0 0 0" />
      <geometry>
        <mesh
          filename="package://robot_des/meshes/base_link.STL" />
      </geometry>
    </collision>
  </link>
  <link
    name="br_Link">
    <inertial>
      <origin
        xyz="-0.020848 -3.9989E-05 2.0411E-05"
        rpy="0 0 0" />
      <mass
        value="0.56255" />
      <inertia
        ixx="0.00080273"
        ixy="1.1803E-11"
        ixz="-1.5327E-11"
        iyy="0.0004545"
        iyz="-5.0114E-08"
        izz="0.00045447" />
    </inertial>
    <visual>
      <origin
        xyz="0 0 0"
        rpy="0 0 0" />
      <geometry>
        <mesh
          filename="package://robot_des/meshes/br_Link.STL" />
      </geometry>
      <material
        name="">
        <color
          rgba="0.75294 0.75294 0.75294 1" />
      </material>
    </visual>
    <collision>
      <origin
        xyz="0 0 0"
        rpy="0 0 0" />
      <geometry>
        <mesh
          filename="package://robot_des/meshes/br_Link.STL" />
      </geometry>
    </collision>
  </link>
  <joint
    name="br_Joint"
    type="continuous">
    <origin
      xyz="0.196 -0.22435 -0.088559"
      rpy="0 0 0" />
    <parent
      link="base_link" />
    <child
      link="br_Link" />
    <axis
      xyz="-1 0 0" />
  </joint>
  <link
    name="bl_Link">
    <inertial>
      <origin
        xyz="0.020846 7.6231E-06 4.4129E-05"
        rpy="0 0 0" />
      <mass
        value="0.55331" />
      <inertia
        ixx="0.00080295"
        ixy="1.0192E-11"
        ixz="-2.7175E-12"
        iyy="0.00045391"
        iyz="1.078E-08"
        izz="0.00045401" />
    </inertial>
    <visual>
      <origin
        xyz="0 0 0"
        rpy="0 0 0" />
      <geometry>
        <mesh
          filename="package://robot_des/meshes/bl_Link.STL" />
      </geometry>
      <material
        name="">
        <color
          rgba="0.75294 0.75294 0.75294 1" />
      </material>
    </visual>
    <collision>
      <origin
        xyz="0 0 0"
        rpy="0 0 0" />
      <geometry>
        <mesh
          filename="package://robot_des/meshes/bl_Link.STL" />
      </geometry>
    </collision>
  </link>
  <joint
    name="bl_Joint"
    type="continuous">
    <origin
      xyz="-0.1955 -0.22436 -0.088723"
      rpy="0 0 0" />
    <parent
      link="base_link" />
    <child
      link="bl_Link" />
    <axis
      xyz="-1 0 0" />
  </joint>
  <link
    name="fl_Link">
    <inertial>
      <origin
        xyz="0.0208481813735867 3.99885874501349E-05 2.04113600184366E-05"
        rpy="0 0 0" />
      <mass
        value="0.56254578668872" />
      <inertia
        ixx="0.000802726596049636"
        ixy="1.18500278027883E-11"
        ixz="1.53838222395849E-11"
        iyy="0.000454501228594865"
        iyz="5.01136294840854E-08"
        izz="0.000454465356701135" />
    </inertial>
    <visual>
      <origin
        xyz="0 0 0"
        rpy="0 0 0" />
      <geometry>
        <mesh
          filename="package://robot_des/meshes/fl_Link.STL" />
      </geometry>
      <material
        name="">
        <color
          rgba="0.752941176470588 0.752941176470588 0.752941176470588 1" />
      </material>
    </visual>
    <collision>
      <origin
        xyz="0 0 0"
        rpy="0 0 0" />
      <geometry>
        <mesh
          filename="package://robot_des/meshes/fl_Link.STL" />
      </geometry>
    </collision>
  </link>
  <joint
    name="fl_Joint"
    type="continuous">
    <origin
      xyz="-0.1955 0.22435 -0.088559"
      rpy="0 0 0" />
    <parent
      link="base_link" />
    <child
      link="fl_Link" />
    <axis
      xyz="-1 0 0" />
  </joint>
  <link
    name="fr_Link">
    <inertial>
      <origin
        xyz="-0.020846 -7.6231E-06 4.4129E-05"
        rpy="0 0 0" />
      <mass
        value="0.55331" />
      <inertia
        ixx="0.00080295"
        ixy="1.0157E-11"
        ixz="2.7635E-12"
        iyy="0.00045391"
        iyz="-1.078E-08"
        izz="0.00045401" />
    </inertial>
    <visual>
      <origin
        xyz="0 0 0"
        rpy="0 0 0" />
      <geometry>
        <mesh
          filename="package://robot_des/meshes/fr_Link.STL" />
      </geometry>
      <material
        name="">
        <color
          rgba="0.75294 0.75294 0.75294 1" />
      </material>
    </visual>
    <collision>
      <origin
        xyz="0 0 0"
        rpy="0 0 0" />
      <geometry>
        <mesh
          filename="package://robot_des/meshes/fr_Link.STL" />
      </geometry>
    </collision>
  </link>
  <joint
    name="fr_Joint"
    type="continuous">
    <origin
      xyz="0.1955 0.22436 -0.088723"
      rpy="0 0 0" />
    <parent
      link="base_link" />
    <child
      link="fr_Link" />
    <axis
      xyz="-1 0 0" />
  </joint>
  <link
    name="Laser_Link">
    <inertial>
      <origin
        xyz="0.015522 -0.0055646 0.017092"
        rpy="0 0 0" />
      <mass
        value="0.05542" />
      <inertia
        ixx="2.3939E-05"
        ixy="-9.4643E-08"
        ixz="-4.9424E-08"
        iyy="2.4757E-05"
        iyz="-3.542E-08"
        izz="3.5106E-05" />
    </inertial>
    <visual>
      <origin
        xyz="0 0 0"
        rpy="0 0 0" />
      <geometry>
        <mesh
          filename="package://robot_des/meshes/Laser_Link.STL" />
      </geometry>
      <material
        name="">
        <color
          rgba="0.29412 0.29412 0.29412 1" />
      </material>
    </visual>
    <collision>
      <origin
        xyz="0 0 0"
        rpy="0 0 0" />
      <geometry>
        <mesh
          filename="package://robot_des/meshes/Laser_Link.STL" />
      </geometry>
    </collision>
  </link>
  <joint
    name="Laser_Joint"
    type="fixed">
    <origin
      xyz="0 0.12413 -0.0564"
      rpy="0 0 0" />
    <parent
      link="base_link" />
    <child
      link="Laser_Link" />
    <axis
      xyz="0 0 0" />
  </joint>
  <link
    name="yuntai_Link">
    <inertial>
      <origin
        xyz="0.0083948 -0.0058886 0.13583"
        rpy="0 0 0" />
      <mass
        value="3.181" />
      <inertia
        ixx="0.002496"
        ixy="0.00022558"
        ixz="0.00018923"
        iyy="0.0038292"
        iyz="-3.2189E-05"
        izz="0.0042073" />
    </inertial>
    <visual>
      <origin
        xyz="0 0 0"
        rpy="0 0 0" />
      <geometry>
        <mesh
          filename="package://robot_des/meshes/yuntai_Link.STL" />
      </geometry>
      <material
        name="">
        <color
          rgba="0.75294 0.75294 0.75294 1" />
      </material>
    </visual>
    <collision>
      <origin
        xyz="0 0 0"
        rpy="0 0 0" />
      <geometry>
        <mesh
          filename="package://robot_des/meshes/yuntai_Link.STL" />
      </geometry>
    </collision>
  </link>
  <joint
    name="yuntai_Joint"
    type="continuous">
    <origin
      xyz="0 0 0.07475"
      rpy="0 0 0" />
    <parent
      link="base_link" />
    <child
      link="yuntai_Link" />
    <axis
      xyz="0 0 1" />
  </joint>
</robot>